const x = 2;

try {
    
    x = 3
    console.log("Tudo ok");

} catch (err) {
    console.log(`Erro: ${err}`);
}